Workbook
Name _Hlk127452852: Gajendra!#REF!
Name _Hlk133227457: Yogesh!$I$86
Name _Hlk147505528: Yogesh!$L$61

Sheet Summary
B1: KARDEXLCS:LIVE OFFER FUNNEL,ACTUALS,DEVIATIONS-2026 | S1: =((T1*94)/12)*1000 -> 23515667 | T1: 3002 | U1: =T1/12 -> 250.16667
B3: OffersHighlights | Q3: Forecast | S3: WEST | T3: SOUTH | U3: NORTH | V3: EAST
Q4: January | R4: =SUM(S4:V4) -> 24074198 | S4: =SUM(Yogesh!F4+Ashraf!AE3+Rahul!AE3+Minesh!AE3) -> 7924702 | T4: =SUM(Gajendra!F4+Pradeep!F4+Sasi!F4) -> 16149496 | U4: =SUM(Vinay!AF3+Nitin!AD4) -> 0 | V4: =Pankaj!AF3 -> 0 | AA4: FromDay1ofeachMonth
B5: Zone | C5: No.ofOffers | D5: OffersValue | E5: OrdersReceived | F5: OpenFunnel | G5: OrderBooking | H5: BUforBooking/2026 | I5: % | J5: BalanceBU | Q5: February | R5: =SUM(S5:V5) -> #REF! | S5: =SUM(Yogesh!F5+Ashraf!AE4+Rahul!AE4+Minesh!AE4) -> 3030491 | T5: =SUM(Gajendra!#REF!+Pradeep!AF5+Sasi!AF5) -> #REF! | U5: =SUM(Vinay!AF4+Nitin!AD5) -> 0 | V5: =Pankaj!AF4 -> 0 | W5: Q1Forecast | X5: Q1BU | Y5: Dev | AA5: Month | AB5: Forecast | AC5: Euro | AD5: StartoftheMonth | AE5: WEST | AF5: SOUTH | AG5: NORTH | AH5: EAST
B6: WEST | C6: =Yogesh!B3+Ashraf!B5+Minesh!B3+Rahul!B3 -> 92 | D6: =C28 -> 72189018 | E6: =D28 -> 16021239 | F6: =Yogesh!X3+Ashraf!X3+Rahul!X3+Minesh!X3 -> 55510963 | G6: =E28 -> 0 | H6: 148500000 | I6: =(H6-G6)/-H6 -> -1 | J6: =H6-G6 -> 148500000 | Q6: March | R6: =SUM(S6:V6) -> #REF! | S6: =SUM(Yogesh!F6+Ashraf!AE5+Rahul!AE5+Minesh!AE5) -> 9822543 | T6: =SUM(Gajendra!#REF!+Pradeep!AF6+Sasi!AF6) -> #REF! | U6: =SUM(Vinay!AF5+Nitin!AD6) -> 0 | V6: =Pankaj!AF5 -> 0 | W6: =SUM(R4:R6) -> #REF! | X6: =S1*3 -> 70547000 | Y6: =SUM(W6-X6)/X6 -> #REF! | AA6: FEB | AB6: =SUM(AE6:AH6) -> 39877565 | AC6: =(AB6/$S$97)/1000 -> 428.79102 | AD6: Febrauary | AE6: 9286760 | AF6: 12347508 | AG6: 17539857 | AH6: 703440
B7: SOUTH | C7: =Gajendra!B3+Pradeep!B3+Sasi!B3 -> 76 | D7: =C45 -> 46386663 | E7: =D45 -> 20071254 | F7: =Gajendra!X3+Pradeep!X3+Sasi!X3 -> 26594061 | G7: =E45 -> 0 | H7: 131625000 | I7: =(H7-G7)/-H7 -> -1 | J7: =H7-G7 -> 131625000 | Q7: April | R7: =SUM(S7:V7) -> #REF! | S7: =SUM(Yogesh!K4+Ashraf!AE6+Rahul!AE6+Minesh!AE6) -> 0 | T7: =SUM(Gajendra!#REF!+Pradeep!#REF!+Sasi!#REF!) -> #REF! | U7: =SUM(Vinay!AF6+Nitin!#REF!) -> #REF! | V7: =Pankaj!AF6 -> 0 | AA7: MAR | AB7: =SUM(AE7:AH7) -> 24653350 | AC7: =(AB7/$S$97)/1000 -> 265.08979 | AD7: March | AE7: 8359399 | AF7: 15286310 | AG7: 1007641 | AH7: 0
B8: NORTH | C8: =Nitin!B3+Vinay!B3 -> 99 | D8: =C62 -> 37280737 | E8: =D62 -> 0 | F8: =Vinay!V5+Nitin!V5 -> 0 | G8: =E62 -> 0 | H8: 47250000 | I8: =(H8-G8)/-H8 -> -1 | J8: =H8-G8 -> 47250000 | Q8: May | R8: =SUM(S8:V8) -> #REF! | S8: =SUM(Yogesh!K5+Ashraf!#REF!+Rahul!#REF!+Minesh!#REF!) -> #REF! | T8: =SUM(Gajendra!#REF!+Pradeep!#REF!+Sasi!#REF!) -> #REF! | U8: =Vinay!#REF!+Nitin!#REF! -> #REF! | V8: =Pankaj!#REF! -> #REF! | W8: Q2Forecast | X8: Q2BU | Y8: Dev | AA8: APR | AB8: =SUM(AE8:AH8) -> 53554063 | AC8: =(AB8/$S$97)/1000 -> 575.85014 | AD8: April | AE8: 35536379 | AF8: 16382704 | AG8: 1634980 | AH8: 0
B9: EAST | C9: =Pankaj!B3 -> 9 | D9: =C79 -> 6040529 | E9: =D79 -> 0 | F9: =Pankaj!V5 -> 0 | G9: =E79 -> 0 | H9: 10125000 | I9: =(H9-G9)/-H9 -> -1 | J9: =H9-G9 -> 10125000 | Q9: June | R9: =SUM(S9:V9) -> #REF! | S9: =SUM(Yogesh!K6+Ashraf!#REF!+Rahul!#REF!+Minesh!#REF!) -> #REF! | T9: =SUM(Gajendra!#REF!+Pradeep!#REF!+Sasi!#REF!) -> #REF! | U9: =SUM(Vinay!#REF!+Nitin!#REF!) -> #REF! | V9: =Pankaj!#REF! -> #REF! | W9: =SUM(R7:R9) -> #REF! | X9: =S1*3 -> 70547000 | Y9: =SUM(W9-X9)/X9 -> #REF! | AA9: MAY | AB9: =SUM(AE9:AH9) -> 45486916 | AC9: =(AB9/$S$97)/1000 -> 489.10662 | AD9: May | AE9: 27968195 | AF9: 9505075.8 | AG9: 6429763 | AH9: 1583882
B10: Total | C10: =SUM(C6:C9) -> 276 | D10: =SUM(D6:D9) -> 1.6189695e+08 | E10: =SUM(E6:E9) -> 36092493 | F10: =SUM(F6:F9) -> 82105024 | G10: =SUM(G6:G9) -> 0 | H10: =SUM(H6:H9) -> 337500000 | I10: =(H10-G10)/-H10 -> -1 | J10: =H10-G10 -> 337500000 | Q10: July | R10: =SUM(S10:V10) -> #REF! | S10: =SUM(Yogesh!P4+Ashraf!#REF!+Rahul!#REF!+Minesh!#REF!) -> #REF! | T10: =SUM(Gajendra!#REF!+Pradeep!#REF!+Sasi!#REF!) -> #REF! | U10: =SUM(Vinay!#REF!+Nitin!#REF!) -> #REF! | V10: =Pankaj!#REF! -> #REF! | AA10: JUN | AB10: =SUM(AE10:AH10) -> 37217079 | AC10: =(AB10/$S$97)/1000 -> 400.18365 | AD10: June | AE10: 24125701 | AF10: 11748673 | AG10: 1203007 | AH10: 139698
Q11: August | R11: =SUM(S11:V11) -> #REF! | S11: =SUM(Yogesh!P5+Ashraf!#REF!+Rahul!#REF!+Minesh!#REF!) -> #REF! | T11: =SUM(Gajendra!#REF!+Pradeep!#REF!+Sasi!#REF!) -> #REF! | U11: =SUM(Vinay!#REF!+Nitin!#REF!) -> #REF! | V11: =Pankaj!#REF! -> #REF! | W11: Q3Forecast | X11: Q3BU | Y11: Dev | AA11: JULY | AB11: =SUM(AE11:AH11) -> 23876033 | AC11: =(AB11/$S$97)/1000 -> 256.73154 | AD11: July | AE11: 8954264 | AF11: 14251915 | AG11: 265000 | AH11: 404854
B12: NOTE:*Marked fields will be filled by Girija | Q12: September | R12: =SUM(S12:V12) -> #REF! | S12: =SUM(Yogesh!P6+Ashraf!#REF!+Rahul!#REF!+Minesh!#REF!) -> #REF! | T12: =SUM(Gajendra!#REF!+Pradeep!#REF!+Sasi!#REF!) -> #REF! | U12: =SUM(Vinay!#REF!+Nitin!#REF!) -> #REF! | V12: =Pankaj!#REF! -> #REF! | W12: =SUM(R10:R12) -> #REF! | X12: =S1*3 -> 70547000 | Y12: =SUM(W12-X12)/X12 -> #REF! | AA12: AUG | AB12: =SUM(AE12:AH12) -> 48070994 | AC12: =(AB12/$S$97)/1000 -> 516.89241 | AD12: August | AE12: 20686301 | AF12: 25365441 | AG12: 1879554 | AH12: 139698
H13: =H6 -> 148500000 | K13: HITRATE | L13: =D28/C28 -> 0.22193457 | Q13: October | R13: =SUM(S13:V13) -> #REF! | S13: =SUM(Yogesh!U4+Ashraf!#REF!+Rahul!#REF!+Minesh!#REF!) -> #REF! | T13: =SUM(Gajendra!AF7+Pradeep!#REF!+Sasi!#REF!) -> #REF! | U13: =SUM(Vinay!#REF!+Nitin!#REF!) -> #REF! | V13: =Pankaj!#REF! -> #REF! | AA13: Sept | AB13: =SUM(AE13:AH13) -> 0 | AC13: =(AB13/$S$97)/1000 -> 0 | AD13: September
B14: WEST | Q14: November | R14: =SUM(S14:V14) -> #REF! | S14: =SUM(Yogesh!U5+Ashraf!#REF!+Rahul!#REF!+Minesh!#REF!) -> #REF! | T14: =SUM(Gajendra!AF8+Pradeep!#REF!+Sasi!#REF!) -> #REF! | U14: =SUM(Vinay!#REF!+Nitin!#REF!) -> #REF! | V14: =Pankaj!#REF! -> #REF! | W14: Q4Forecast | X14: Q4BU | Y14: Dev | AA14: Oct | AB14: =SUM(AE14:AH14) -> 0 | AC14: =(AB14/$S$97)/1000 -> 0 | AD14: October
B15: Month | C15: Offers/Value | D15: OrderReceived | E15: *OrdersBooked | F15: DevORvsBooked | G15: *OrdersIn-Hand | H15: BU/Monthly | I15: BookedvsBU | J15: %Dev | K15: OfferBUMonthly | L15: %Dev | Q15: December | R15: =SUM(S15:V15) -> #REF! | S15: =SUM(Yogesh!U6+Ashraf!#REF!+Rahul!#REF!+Minesh!#REF!) -> #REF! | T15: =SUM(Gajendra!AF9+Pradeep!#REF!+Sasi!#REF!) -> #REF! | U15: =SUM(Vinay!#REF!+Nitin!#REF!) -> #REF! | V15: =Pankaj!#REF! -> #REF! | W15: =SUM(R13:R15) -> #REF! | X15: =S1*3 -> 70547000 | Y15: =SUM(W15-X15)/X15 -> #REF! | AA15: Nov | AB15: =SUM(AE15:AH15) -> 0 | AC15: =(AB15/$S$97)/1000 -> 0 | AD15: November
B16: Januray | C16: =Yogesh!D4+Ashraf!D4+Rahul!D4+Minesh!D4 -> 68643485 | D16: =Yogesh!E4+Ashraf!E4+Rahul!E4+Minesh!E4 -> 15643879 | F16: =D16-E16 -> 15643879 | H16: =$H$13/12 -> 12375000 | I16: =H16-E16 -> 12375000 | J16: =(E16-H16)/E16 -> #DIV/0! | K16: =H16*4 -> 49500000 | L16: =(K16-C16)/K16 -> -0.38673707 | AA16: Dec | AB16: =SUM(AE16:AH16) -> 0 | AC16: =(AB16/$S$97)/1000 -> 0 | AD16: December
B17: Febraury | C17: =Yogesh!D5+Ashraf!D5+Rahul!D5+Minesh!D5 -> 3545533 | D17: =Yogesh!E5+Ashraf!E5+Rahul!E5+Minesh!E5 -> 377360 | F17: =D17-E17 -> 377360 | H17: =$H$13/12 -> 12375000 | I17: =H17-E17 -> 12375000 | J17: =(E17-H17)/E17 -> #DIV/0! | K17: =H17*4 -> 49500000 | L17: =(K17-C17)/K17 -> 0.92837307 | Q17: Producttype | R17: Yogesh | S17: Ashraf | T17: Rahul | U17: Minesh | V17: WEST | X17: Producttype | Y17: TotalofAllZones
B18: March | C18: =Yogesh!D6+Ashraf!D6+Rahul!D6+Minesh!D6 -> 0 | D18: =Yogesh!E6+Ashraf!E6+Rahul!E6+Minesh!E6 -> 0 | F18: =D18-E18 -> 0 | H18: =$H$13/12 -> 12375000 | I18: =H18-E18 -> 12375000 | J18: =(E18-H18)/E18 -> #DIV/0! | K18: =H18*4 -> 49500000 | L18: =(K18-C18)/K18 -> 1 | Q18: Contract | R18: =SUMIF(Yogesh!$J$8:$J$121,"Contract",Yogesh!$N$8:$N$122) -> 1768409 | S18: =SUMIF(Ashraf!$J$7:$J$119,"Contract",Ashraf!$N$7:$N$120) -> 3505000 | T18: =SUMIF(Rahul!$J$7:$J$111,"Contract",Rahul!$N$7:$N$112) -> 6047555 | U18: =SUMIF(Minesh!$J$7:$J$111,"Contract",Minesh!$N$7:$N$112) -> 3774885 | V18: =SUM(R18:U18) -> 15095849 | X18: Contract | Y18: =SUM(R18:X18) -> 30191698
B19: April | C19: =Yogesh!I4+Ashraf!I4+Rahul!I4+Minesh!I4 -> 0 | D19: =Yogesh!J4+Ashraf!J4+Rahul!J4+Minesh!J4 -> 0 | F19: =D19-E19 -> 0 | H19: =$H$13/12 -> 12375000 | I19: =H19-E19 -> 12375000 | J19: =(E19-H19)/E19 -> #DIV/0! | K19: =H19*4 -> 49500000 | L19: =(K19-C19)/K19 -> 1 | Q19: BDSpare | R19: =SUMIF(Yogesh!$J$9:$J$122,"BDSpare",Yogesh!$N$9:S34) -> 0 | S19: =SUMIF(Ashraf!$J$7:$J$120,"BDSpare",Ashraf!$N$7:T43) -> 0 | T19: =SUMIF(Rahul!$J$7:$J$112,"BDSpare",Rahul!$N$7:U24) -> 0 | U19: =SUMIF(Minesh!$J$7:$J$112,"BDSpare",Minesh!$N$7:V24) -> 0 | V19: =SUM(R19:U19) -> 0 | X19: BDSpare | Y19: =SUM(R19:X19) -> 0
B20: May | C20: =Yogesh!I5+Ashraf!I5+Rahul!I5+Minesh!I5 -> 0 | D20: =Yogesh!J5+Ashraf!J5+Rahul!J5+Minesh!J5 -> 0 | F20: =D20-E20 -> 0 | H20: =$H$13/12 -> 12375000 | I20: =H20-E20 -> 12375000 | J20: =(E20-H20)/E20 -> #DIV/0! | K20: =H20*4 -> 49500000 | L20: =(K20-C20)/K20 -> 1 | Q20: SPP | R20: =SUMIF(Yogesh!$J$10:$J$123,"SPP",Yogesh!$N$10:$N$124) -> 6778394 | S20: =SUMIF(Ashraf!$J$7:$J$121,"SPP",Ashraf!$N$7:$N$122) -> 6821856 | T20: =SUMIF(Rahul!$J$7:$J$113,"SPP",Rahul!$N$7:$N$114) -> 8197401 | U20: =SUMIF(Minesh!$J$7:$J$113,"SPP",Minesh!$N$7:$N$114) -> 825600 | V20: =SUM(R20:U20) -> 22623251 | X20: SPP | Y20: =SUM(R20:X20) -> 45246502
B21: June | C21: =Yogesh!I6+Ashraf!I6+Rahul!I6+Minesh!I6 -> 0 | D21: =Yogesh!J6+Ashraf!J6+Rahul!J6+Minesh!J6 -> 0 | F21: =D21-E21 -> 0 | H21: =$H$13/12 -> 12375000 | I21: =H21-E21 -> 12375000 | J21: =(E21-H21)/E21 -> #DIV/0! | K21: =H21*4 -> 49500000 | L21: =(K21-C21)/K21 -> 1 | Q21: Relocation | R21: =SUMIF(Yogesh!$J$11:$J$124,"Relocation",Yogesh!$N$11:$N$125) -> 2600000 | S21: =SUMIF(Ashraf!$J$7:$J$122,"Relocation",Ashraf!$N$7:$N$123) -> 730000 | T21: =SUMIF(Rahul!$J$7:$J$114,"Relocation",Rahul!$N$7:$N$115) -> 0 | U21: =SUMIF(Minesh!$J$7:$J$114,"Relocation",Minesh!$N$7:$N$115) -> 0 | V21: =SUM(R21:U21) -> 3330000 | X21: Relocation | Y21: =SUM(R21:X21) -> 6660000
B22: July | C22: =Yogesh!N4+Ashraf!N4+Rahul!N4+Minesh!N4 -> 0 | D22: =Yogesh!O4+Ashraf!O4+Rahul!O4+Minesh!O4 -> 0 | F22: =D22-E22 -> 0 | H22: =$H$13/12 -> 12375000 | I22: =H22-E22 -> 12375000 | J22: =(E22-H22)/E22 -> #DIV/0! | K22: =H22*4 -> 49500000 | L22: =(K22-C22)/K22 -> 1 | Q22: Software | R22: =SUMIF(Yogesh!$J$12:$J$125,"Software",Yogesh!$N$12:$N$126) -> 2228000 | S22: =SUMIF(Ashraf!$J$7:$J$123,"Software",Ashraf!$N$7:$N$124) -> 64000 | T22: =SUMIF(Rahul!$J$7:$J$115,"Software",Rahul!$N$7:$N$116) -> 0 | U22: =SUMIF(Minesh!$J$7:$J$115,"Software",Minesh!$N$7:$N$116) -> 0 | V22: =SUM(R22:U22) -> 2292000 | X22: Software | Y22: =SUM(R22:X22) -> 4584000
B23: August | C23: =Yogesh!N5+Ashraf!N5+Rahul!N5+Minesh!N5 -> 0 | D23: =Yogesh!O5+Ashraf!O5+Rahul!O5+Minesh!O5 -> 0 | F23: =D23-E23 -> 0 | H23: =$H$13/12 -> 12375000 | I23: =H23-E23 -> 12375000 | J23: =(E23-H23)/E23 -> #DIV/0! | K23: =H23*4 -> 49500000 | L23: =(K23-C23)/K23 -> 1 | Q23: BDCharges | R23: =SUMIF(Yogesh!$J$13:$J$126,"BDCharges",Yogesh!$N$13:$N$127) -> 0 | S23: =SUMIF(Ashraf!$J$7:$J$124,"BDCharges",Ashraf!$N$7:$N$125) -> 0 | T23: =SUMIF(Rahul!$J$7:$J$116,"BDCharges",Rahul!$N$7:$N$117) -> 28500 | U23: =SUMIF(Minesh!$J$7:$J$116,"BDCharges",Minesh!$N$7:$N$117) -> 22500 | V23: =SUM(R23:U23) -> 51000 | X23: BDCharges | Y23: =SUM(R23:X23) -> 102000
B24: September | C24: =Yogesh!N6+Ashraf!N6+Rahul!N6+Minesh!N6 -> 0 | D24: =Yogesh!O6+Ashraf!O6+Rahul!O6+Minesh!O6 -> 0 | F24: =D24-E24 -> 0 | H24: =$H$13/12 -> 12375000 | I24: =H24-E24 -> 12375000 | J24: =(E24-H24)/E24 -> #DIV/0! | K24: =H24*4 -> 49500000 | L24: =(K24-C24)/K24 -> 1 | Q24: Retrofitkit | R24: =SUMIF(Yogesh!$J$14:$J$127,"Retrofitkit",Yogesh!$N$14:$N$128) -> 1248375 | S24: =SUMIF(Ashraf!$J$7:$J$125,"Retrofitkit",Ashraf!$N$7:$N$126) -> 13500000 | T24: =SUMIF(Rahul!$J$7:$J$117,"Retrofitkit",Rahul!$N$7:$N$118) -> 1224700 | U24: =SUMIF(Minesh!$J$7:$J$117,"Minesh",Rahul!$N$7:$N$118) -> 0 | V24: =SUM(R24:U24) -> 15973075 | X24: Retrofitkit | Y24: =SUM(R24:X24) -> 31946150
B25: October | C25: =Yogesh!S4+Ashraf!S4+Rahul!S4+Minesh!S4 -> 0 | D25: =Yogesh!T4+Ashraf!T4+Rahul!T4+Minesh!T4 -> 0 | F25: =D25-E25 -> 0 | H25: =$H$13/12 -> 12375000 | I25: =H25-E25 -> 12375000 | J25: =(E25-H25)/E25 -> #DIV/0! | K25: =H25*4 -> 49500000 | L25: =(K25-C25)/K25 -> 1 | Q25: Upgradekit | R25: =SUMIF(Yogesh!$J$15:$J$128,"Upgradekit",Yogesh!$N$15:$N$129) -> 5932179 | S25: =SUMIF(Ashraf!$J$7:$J$126,"Upgradekit",Ashraf!$N$7:$N$127) -> 2918203 | T25: =SUMIF(Rahul!$J$7:$J$118,"Upgradekit",Rahul!$N$7:$N$119) -> 1553708 | U25: =SUMIF(Minesh!$J$7:$J$118,"Upgradekit",Minesh!$N$7:$N$119) -> 0 | V25: =SUM(R25:U25) -> 10404090 | X25: Upgradekit | Y25: =SUM(R25:X25) -> 20808180
B26: November | C26: =Yogesh!S5+Ashraf!S5+Rahul!S5+Minesh!S5 -> 0 | D26: =Yogesh!T5+Ashraf!T5+Rahul!T5+Minesh!T5 -> 0 | F26: =D26-E26 -> 0 | H26: =$H$13/12 -> 12375000 | I26: =H26-E26 -> 12375000 | J26: =(E26-H26)/E26 -> #DIV/0! | K26: =H26*4 -> 49500000 | L26: =(K26-C26)/K26 -> 1 | Q26: Training | R26: =SUMIF(Yogesh!$J$16:$J$129,"Training",Yogesh!$N$16:$N$130) -> 0 | S26: =SUMIF(Ashraf!$J$7:$J$127,"Training",Ashraf!$N$7:$N$128) -> 0 | T26: =SUMIF(Rahul!$J$7:$J$119,"Training",Rahul!$N$7:$N$120) -> 0 | U26: =SUMIF(Minesh!$J$7:$J$119,"Training",Minesh!$N$7:$N$120) -> 0 | V26: =SUM(R26:U26) -> 0 | X26: Training | Y26: =SUM(R26:X26) -> 0
B27: December | C27: =Yogesh!S6+Ashraf!S6+Rahul!S6+Minesh!S6 -> 0 | D27: =Yogesh!T6+Ashraf!T6+Rahul!T6+Minesh!T6 -> 0 | F27: =D27-E27 -> 0 | H27: =$H$13/12 -> 12375000 | I27: =H27-E27 -> 12375000 | J27: =(E27-H27)/E27 -> #DIV/0! | K27: =H27*4 -> 49500000 | L27: =(K27-C27)/K27 -> 1 | Q27: MidlifeUpgrade | R27: =SUMIF(Yogesh!$J$17:$J$130,"MidlifeUpgrade",Yogesh!$N$17:$N$131) -> 0 | S27: =SUMIF(Ashraf!$J$7:$J$128,"MidlifeUpgrade",Ashraf!$N$7:$N$129) -> 550271 | T27: =SUMIF(Rahul!$J$7:$J$120,"MidlifeUpgrade",Rahul!$N$7:$N$121) -> 1618603 | U27: =SUMIF(Minesh!$J$7:$J$120,"MidlifeUpgrade",Minesh!$N$7:$N$121) -> 0 | V27: =SUM(R27:U27) -> 2168874 | X27: MidlifeUpgrade | Y27: =SUM(R27:X27) -> 4337748
B28: Total | C28: =SUM(C16:C27) -> 72189018 | D28: =SUM(D16:D27) -> 16021239 | E28: =SUM(E16:E27) -> 0 | F28: =SUM(F16:F27) -> 16021239 | H28: =SUM(H16:H27) -> 148500000 | I28: =SUM(I16:I27) -> 148500000 | K28: =SUM(K16:K27) -> 594000000 | L28: =(K28-C28)/K28 -> 0.87846967 | Q28: Total | R28: =SUM(R18:R27) -> 20555357 | S28: =SUM(S18:S27) -> 28089330 | T28: =SUM(T18:T27) -> 18670467 | U28: =SUM(U18:U27) -> 4622985 | V28: =SUM(R28:U28) -> 71938139 | X28: Total | Y28: =SUM(Y18:Y27) -> 143876278
H30: =H7 -> 131625000 | K30: HITRATE | L30: =D45/C45 -> 0.4326945 | Q30: Producttype | R30: Gajendra | S30: Pradeep | T30: Sasi | V30: South
B31: SOUTH | Q31: Contract | R31: =SUMIF(Gajendra!$J$7:$J$102,"Contract",Gajendra!$N$7:$N$103) -> 2959490 | S31: =SUMIF(Pradeep!$J$7:$J$111,"Contract",Pradeep!$N$7:$N$112) -> 9975583 | T31: =SUMIF(Sasi!$J$7:$J$115,"Contract",Sasi!$N$7:$N$116) -> 1636650 | V31: =SUM(R31:U31) -> 14571723
B32: Month | C32: Offers/Value | D32: OrderReceived | E32: *OrderBooked | F32: DevORvsBooked | G32: *OrdersIn-Hand | H32: BU/Monthly | I32: BookedvsBU | J32: %Dev | K32: OfferBUMonthly | L32: %Dev | Q32: BDSpare | R32: =SUMIF(Gajendra!$J$7:$J$103,"BDSpare",Gajendra!$N$7:W27) -> 0 | S32: =SUMIF(Pradeep!$J$7:$J$112,"BDSpare",Pradeep!$N$7:X24) -> 0 | T32: =SUMIF(Sasi!$J$7:$J$116,"BDSpare",Sasi!$N$7:Y25) -> 0 | V32: =SUM(R32:U32) -> 0
B33: Januray | C33: =Gajendra!D4+Pradeep!D4+Sasi!D4 -> 45656721 | D33: =Gajendra!E4+Pradeep!E4+Sasi!E4 -> 16655788 | F33: =D33-E33 -> 16655788 | H33: =$H$30/12 -> 10968750 | I33: =H33-E33 -> 10968750 | J33: =(E33-H33)/E33 -> #DIV/0! | K33: =H33*4 -> 43875000 | L33: =(K33-C33)/K33 -> -0.040609026 | Q33: SPP | R33: =SUMIF(Gajendra!$J$7:$J$104,"SPP",Gajendra!$N$7:$N$104) -> 865031 | S33: =SUMIF(Pradeep!$J$7:$J$113,"SPP",Pradeep!$N$7:$N$114) -> 413320 | T33: =SUMIF(Sasi!$J$7:$J$117,"SPP",Sasi!$N$7:$N$118) -> 926156 | V33: =SUM(R33:U33) -> 2204507
B34: Febraury | C34: =Gajendra!D5+Pradeep!D5+Sasi!D5 -> 0 | D34: =Gajendra!E5+Pradeep!E5+Sasi!E5 -> 2685524 | F34: =D34-E34 -> 2685524 | H34: =$H$30/12 -> 10968750 | I34: =H34-E34 -> 10968750 | J34: =(E34-H34)/E34 -> #DIV/0! | K34: =H34*4 -> 43875000 | L34: =(K34-C34)/K34 -> 1 | Q34: Relocation | R34: =SUMIF(Gajendra!$J$7:$J$104,"Relocation",Gajendra!$N$7:$N$104) -> 1204160 | S34: =SUMIF(Pradeep!$J$7:$J$114,"Relocation",Pradeep!$N$7:$N$115) -> 984000 | T34: =SUMIF(Sasi!$J$7:$J$118,"Relocation",Sasi!$N$7:$N$119) -> 0 | V34: =SUM(R34:U34) -> 2188160
B35: March | C35: =Gajendra!D6+Pradeep!D6+Sasi!D6 -> 0 | D35: =Gajendra!E6+Pradeep!E6+Sasi!E6 -> 0 | F35: =D35-E35 -> 0 | H35: =$H$30/12 -> 10968750 | I35: =H35-E35 -> 10968750 | J35: =(E35-H35)/E35 -> #DIV/0! | K35: =H35*4 -> 43875000 | L35: =(K35-C35)/K35 -> 1 | Q35: Software | R35: =SUMIF(Gajendra!$J$7:$J$104,"Software",Gajendra!$N$7:$N$104) -> 0 | S35: =SUMIF(Pradeep!$J$7:$J$115,"Software",Pradeep!$N$7:$N$116) -> 0 | T35: =SUMIF(Sasi!$J$7:$J$119,"Software",Sasi!$N$7:$N$120) -> 0 | V35: =SUM(R35:U35) -> 0
B36: April | C36: =Gajendra!I4+Pradeep!I4+Sasi!I4 -> 0 | D36: =Gajendra!I4+Pradeep!J4+Sasi!J4 -> 0 | F36: =D36-E36 -> 0 | H36: =$H$30/12 -> 10968750 | I36: =H36-E36 -> 10968750 | J36: =(E36-H36)/E36 -> #DIV/0! | K36: =H36*4 -> 43875000 | L36: =(K36-C36)/K36 -> 1 | Q36: BDCharges | R36: =SUMIF(Gajendra!$J$7:$J$104,"BDCharges",Gajendra!$N$7:$N$104) -> 0 | S36: =SUMIF(Pradeep!$J$7:$J$116,"BDCharges",Pradeep!$N$7:$N$117) -> 0 | T36: =SUMIF(Sasi!$J$7:$J$120,"BDCharges",Sasi!$N$7:$N$121) -> 0 | V36: =SUM(R36:U36) -> 0
B37: May | C37: =Gajendra!I5+Pradeep!I5+Sasi!I5 -> 0 | D37: =Gajendra!I5+Pradeep!J5+Sasi!J5 -> 0 | F37: =D37-E37 -> 0 | H37: =$H$30/12 -> 10968750 | I37: =H37-E37 -> 10968750 | J37: =(E37-H37)/E37 -> #DIV/0! | K37: =H37*4 -> 43875000 | L37: =(K37-C37)/K37 -> 1 | Q37: Retrofitkit | R37: =SUMIF(Gajendra!$J$7:$J$104,"Gajendra",Rahul!$N$7:$N$118) -> 0 | S37: =SUMIF(Pradeep!$J$7:$J$117,"Pradeep",Rahul!$N$7:$N$118) -> 0 | T37: =SUMIF(Sasi!$J$7:$J$121,"Retrofitkit",Sasi!$N$7:$N$122) -> 0 | V37: =SUM(R37:U37) -> 0
B38: June | C38: =Gajendra!I6+Pradeep!I6+Sasi!I6 -> 729941.76 | D38: =Gajendra!I6+Pradeep!J6+Sasi!J6 -> 0 | F38: =D38-E38 -> 0 | H38: =$H$30/12 -> 10968750 | I38: =H38-E38 -> 10968750 | J38: =(E38-H38)/E38 -> #DIV/0! | K38: =H38*4 -> 43875000 | L38: =(K38-C38)/K38 -> 0.98336315 | Q38: Upgradekit | R38: =SUMIF(Gajendra!$J$7:$J$105,"Upgradekit",Gajendra!$N$7:$N$106) -> 0 | S38: =SUMIF(Pradeep!$J$7:$J$118,"Upgradekit",Pradeep!$N$7:$N$119) -> 0 | T38: =SUMIF(Sasi!$J$7:$J$122,"Upgradekit",Sasi!$N$7:$N$123) -> 0 | V38: =SUM(R38:U38) -> 0
B39: July | C39: =Gajendra!N4+Pradeep!N4+Sasi!N4 -> 0 | D39: =Gajendra!O4+Pradeep!O4+Sasi!O4 -> 0 | F39: =D39-E39 -> 0 | H39: =$H$30/12 -> 10968750 | I39: =H39-E39 -> 10968750 | J39: =(E39-H39)/E39 -> #DIV/0! | K39: =H39*4 -> 43875000 | L39: =(K39-C39)/K39 -> 1 | Q39: Training | R39: =SUMIF(Gajendra!$J$8:$J$106,"Training",Gajendra!$N$8:$N$107) -> 0 | S39: =SUMIF(Pradeep!$J$7:$J$119,"Training",Pradeep!$N$7:$N$120) -> 0 | T39: =SUMIF(Sasi!$J$7:$J$123,"Training",Sasi!$N$7:$N$124) -> 0 | V39: =SUM(R39:U39) -> 0
B40: August | C40: =Gajendra!N5+Pradeep!N5+Sasi!N5 -> 0 | D40: =Gajendra!O5+Pradeep!O5+Sasi!O5 -> 0 | F40: =D40-E40 -> 0 | H40: =$H$30/12 -> 10968750 | I40: =H40-E40 -> 10968750 | J40: =(E40-H40)/E40 -> #DIV/0! | K40: =H40*4 -> 43875000 | L40: =(K40-C40)/K40 -> 1 | Q40: MidlifeUpgrade | R40: =SUMIF(Gajendra!$J$9:$J$107,"MidlifeUpgrade",Gajendra!$N$9:$N$108) -> 0 | S40: =SUMIF(Pradeep!$J$7:$J$120,"MidlifeUpgrade",Pradeep!$N$7:$N$121) -> 0 | T40: =SUMIF(Sasi!$J$7:$J$124,"MidlifeUpgrade",Sasi!$N$7:$N$125) -> 0 | V40: =SUM(R40:U40) -> 0
B41: September | C41: =Gajendra!N6+Pradeep!N6+Sasi!N6 -> 0 | D41: =Gajendra!O6+Pradeep!O6+Sasi!O6 -> 729941.76 | F41: =D41-E41 -> 729941.76 | H41: =$H$30/12 -> 10968750 | I41: =H41-E41 -> 10968750 | J41: =(E41-H41)/E41 -> #DIV/0! | K41: =H41*4 -> 43875000 | L41: =(K41-C41)/K41 -> 1 | Q41: Total | R41: =SUM(R31:R40) -> 5028681 | S41: =SUM(S31:S40) -> 11372903 | T41: =SUM(T31:T40) -> 2562806 | V41: =SUM(V31:V40) -> 18964390
B42: October | C42: =Gajendra!S4+Pradeep!S4+Sasi!S4 -> 0 | D42: =Gajendra!T4+Pradeep!T4+Sasi!T4 -> 0 | F42: =D42-E42 -> 0 | H42: =$H$30/12 -> 10968750 | I42: =H42-E42 -> 10968750 | J42: =(E42-H42)/E42 -> #DIV/0! | K42: =H42*4 -> 43875000 | L42: =(K42-C42)/K42 -> 1
...

Sheet Yogesh
A2: KARDEX INDIA - LIVE OFFER FUNEL - YOGESH - WEST
A3: Total Offers | B3: =COUNTA(B8:B1429) -> 35 | C3: Month | D3: Offers Total | E3: Order received | F3: Forecast | G3: Forecast- Po Received | H3: Month | I3: Offers Total | J3: Order received | K3: Forecast | L3: Forecast- Po Received | M3: Month | N3: Offers Total | O3: Order received | P3: Forecast | Q3: Forecast- Po Received | R3: Month | S3: Offers Total | T3: Order received | U3: Forecast | V3: Forecast- Po Received | W3: Total Open Funnel | X3: =SUM(V8:V1999) -> 18691333
C4: January | D4: =SUMIF($O$8:$O$408,"January",$N$8:$N$408) -> 20777736 | E4: =SUMIF($U$8:$U$408,"January",$T$8:$T$408) -> 2086403 | F4: =SUMIF($P$8:$P$427,"January",$N$8:$N$427) -> 7924702 | G4: =F4-E4 -> 5838299 | H4: April | I4: =SUMIF($O$8:$O$408,"April",$N$8:$N$408) -> 0 | J4: =SUMIF($U$8:$U$408,"April",$T$8:$T$408) -> 0 | K4: =SUMIF($P$8:$P$427,"April",$N$8:$N$427) -> 0 | L4: =K4-J4 -> 0 | M4: July | N4: =SUMIF($O$8:$O$408,"July",$N$8:$N$408) -> 0 | O4: =SUMIF($U$8:$U$408,"July",$T$8:$T$408) -> 0 | P4: =SUMIF($P$8:$P$427,"July",$N$8:$N$427) -> 0 | Q4: =P4-O4 -> 0 | R4: October | S4: =SUMIF($O$8:$O$408,"October",$N$8:$N$408) -> 0 | T4: =SUMIF($U$8:$U$408,"October",$T$8:$T$408) -> 0 | U4: =SUMIF($P$8:$P$427,"October",$N$8:$N$427) -> 0 | V4: =U4-T4 -> 0
C5: February | D5: =SUMIF($O$8:$O$408,"February",$N$8:$N$408) -> 0 | E5: =SUMIF($U$8:$U$408,"February",$T$8:$T$408) -> 0 | F5: =SUMIF($P$8:$P$427,"February",$N$8:$N$427) -> 3030491 | G5: =F5-E5 -> 3030491 | H5: May | I5: =SUMIF($O$8:$O$408,"May",$N$8:$N$408) -> 0 | J5: =SUMIF($U$8:$U$408,"May",$T$8:$T$408) -> 0 | K5: =SUMIF($P$8:$P$427,"May",$N$8:$N$427) -> 0 | L5: =K5-J5 -> 0 | M5: August | N5: =SUMIF($O$8:$O$408,"August",$N$8:$N$408) -> 0 | O5: =SUMIF($U$8:$U$408,"August",$T$8:$T$408) -> 0 | P5: =SUMIF($P$8:$P$427,"August",$N$8:$N$427) -> 0 | Q5: =P5-O5 -> 0 | R5: November | S5: =SUMIF($O$8:$O$408,"November",$N$8:$N$408) -> 0 | T5: =SUMIF($U$8:$U$408,"November",$T$8:$T$408) -> 0 | U5: =SUMIF($P$8:$P$427,"November",$N$8:$N$427) -> 0 | V5: =U5-T5 -> 0
C6: March | D6: =SUMIF($O$8:$O$408,"March",$N$8:$N$408) -> 0 | E6: =SUMIF($U$8:$U$408,"March",$T$8:$T$408) -> 0 | F6: =SUMIF($P$8:$P$427,"March",$N$8:$N$427) -> 9822543 | G6: =F6-E6 -> 9822543 | H6: June | I6: =SUMIF($O$8:$O$408,"June",$N$8:$N$408) -> 0 | J6: =SUMIF($U$8:$U$408,"June",$T$8:$T$408) -> 0 | K6: =SUMIF($P$8:$P$427,"June",$N$8:$N$427) -> 0 | L6: =K6-J6 -> 0 | M6: September | N6: =SUMIF($O$8:$O$408,"September",$N$8:$N$408) -> 0 | O6: =SUMIF($U$8:$U$408,"September",$T$8:$T$408) -> 0 | P6: =SUMIF($P$8:$P$427,"September",$N$8:$N$427) -> 0 | Q6: =P6-O6 -> 0 | R6: December | S6: =SUMIF($O$8:$O$408,"December",$N$8:$N$408) -> 0 | T6: =SUMIF($U$8:$U$408,"December",$T$8:$T$408) -> 0 | U6: =SUMIF($P$8:$P$427,"December",$N$8:$N$427) -> 0 | V6: =U6-T6 -> 0
A7: SL | B7: Reg Date | C7: Company | D7: Location | E7: Department | F7: Contact Person Name | G7: Contact Number | H7: E-Mail ID | I7: Machine Serial Number | J7: Product Type | K7: Lead | L7: Offer Reference Number | M7: Offer Reference Date | N7: Offer Value | O7: Offer Month | P7: PO Expected Month | Q7: Probabality in Percentage | R7: PO Number | S7: PO Date | T7: PO Value | U7: PO Received Month | V7: Open Funnel | W7: Remarks | X7: Status | Y7: Booking Date in SAP B1 | Z7: Offer Entered in CRM | AA7: Offer Closed in CRM
A8: 1 | B8: 45740 | C8: Rieter India Pvt Ltd | D8: Pune | E8: stores | F8: Manoj Rasal | G8: 9822192492 | H8: manoj.rasal@rieter.com | I8: 21002906/001 | J8: Contract | K8: No | L8: KXIND/W/MC/YD/25025 | M8: 45718 | N8: 67000 | O8: January | P8: January | Q8: 1 | R8: 4504578229 | S8: 45779 | T8: 67000 | U8: January | V8: =Table62689345[[#This Row],[Offer Value]]-Table62689345[[#This Row],[PO Value]] -> 0
A9: 2 | B9: 45961 | C9: Carraro India Pvt Limited | D9: Pune | E9: stores | F9: Ravindra khambayat | G9: 9822840261 | H9: Ravindra_Khambayat@carraro.com | I9: 08001856/001 | J9: SPP | K9: Yes | L9: KXIND/W/YD/SPP/25073 | M9: 45945 | N9: 222379 | O9: January | P9: January | Q9: 1 | R9: 4500565834 4500570108 | S9: 46000 | T9: 216507 | U9: January | V9: =Table62689345[[#This Row],[Offer Value]]-Table62689345[[#This Row],[PO Value]] -> 5872
A10: 3 | B10: 45961 | C10: Bridgestone India Pvt.Ltd. | D10: Pune | E10: HR store | F10: Mangesh Engale | G10: 9607328084 | H10: mangesh-ingle@bridgestone.co.in | I10: 18005925/001 | J10: Contract | K10: No | L10: KXIND/W/YD/MC/25077 | M10: 45957 | N10: 118009 | O10: January | P10: January | Q10: 1 | R10: 4500089503 | S10: 45980 | T10: 118009 | U10: January | V10: =Table62689345[[#This Row],[Offer Value]]-Table62689345[[#This Row],[PO Value]] -> 0
A11: 4 | B11: 46010 | C11: Eagle Burgmann India Pvt Ltd | D11: Pune | E11: stores | F11: Mahesh Hole | G11: 9373850080 | H11: Mahesh.Hole@in.eagleburgmann.com | I11: 08004851/001 | J11: SPP | K11: Yes | L11: KXIND/W/SPP/YD/25089 | M11: 45999 | N11: 640000 | O11: January | P11: January | Q11: 1 | R11: 2560209 | S11: 46008 | T11: 615210 | U11: January | V11: =Table62689345[[#This Row],[Offer Value]]-Table62689345[[#This Row],[PO Value]] -> 24790
A12: 5 | B12: 45667 | C12: Tata Motors LTD | D12: Pune | E12: D blockstore | F12: pankaj Badhe | G12: 8237003520 | H12: badhe.pankaj@tatamotors.com | I12: 16002093/001 | J12: Relocation | K12: No | L12: KXIND/W/SPP/YD24-01 | M12: 45394 | N12: 385000 | O12: January | P12: January | Q12: 0.5 | V12: =Table62689345[[#This Row],[Offer Value]]-Table62689345[[#This Row],[PO Value]] -> 385000
A13: 6 | B13: 45667 | C13: Tata Motors LTD | D13: Pune | E13: D blockstore | F13: pankaj Badhe | G13: 8237003521 | H13: badhe.pankaj@tatamotors.com | I13: 16002093/002 | J13: Relocation | K13: No | L13: KXIND/W/SPP/YD24-01 | M13: 45394 | N13: 385000 | O13: January | P13: January | Q13: 0.5 | V13: =Table62689345[[#This Row],[Offer Value]]-Table62689345[[#This Row],[PO Value]] -> 385000
A14: 7 | B14: 45922 | C14: Tata Motors LTD | D14: Pune | E14: Cblk Maint | F14: Amit sharma | G14: 9011018387 | H14: s.amit1@tatamotors.com | I14: 06008006/001 | J14: Software | K14: Yes | L14: KRIND/SA/OTH/520025 | M14: 45916 | N14: 1378000 | O14: January | P14: January | Q14: 0.3 | T14: 0 | V14: =Table62689345[[#This Row],[Offer Value]]-Table62689345[[#This Row],[PO Value]] -> 1378000
A15: 8 | B15: 45999 | C15: Tata motors passenger vehicles Limted (Tata Motors Ltd) | D15: Pune | E15: TCF | F15: Depak Dalvi | G15: 9850341560 | H15: DGD793450@tatamotors.com | I15: 08000931/001 | J15: SPP | K15: Yes | L15: KXIND/W/YD/SPP/25088 | M15: 45989 | N15: 346200 | O15: January | P15: January | Q15: 0.2 | V15: =Table62689345[[#This Row],[Offer Value]]-Table62689345[[#This Row],[PO Value]] -> 346200
A16: 9 | B16: 45705 | C16: Lupin Limited | D16: Nagpur | E16: Stores | F16: Mukesh Namdev | G16: +91 8959678211 | H16: mukeshnamdev@lupin.com | I16: 23005504/001 | J16: Contract | K16: Yes | L16: KXIND/W/YD/MC/2509R | M16: 45863 | N16: 55000 | O16: January | P16: January | Q16: 0.5 | T16: 55000 | U16: January | V16: =Table62689345[[#This Row],[Offer Value]]-Table62689345[[#This Row],[PO Value]] -> 0
A17: 10 | B17: 45922 | C17: Tata Motors LTD | D17: Pune | E17: Cblk Maint | F17: Amit sharma | G17: 9011018387 | H17: s.amit1@tatamotors.com | I17: 06008006/001 | J17: Relocation | K17: Yes | L17: KRIND/W/YD/RE/25069 | M17: 15-092025 | N17: 1160000 | O17: January | P17: January | Q17: 0.3 | V17: =Table62689345[[#This Row],[Offer Value]]-Table62689345[[#This Row],[PO Value]] -> 1160000
A18: 11 | B18: 45922 | C18: Bajaj Auto Ltd | D18: Pune | E18: Engine Assembly | F18: Rakesh Kirange | G18: 9850043641 | H18: rnkirange@bajajauto.co.in | I18: 19003778/001 | J18: Software | K18: Yes | L18: KRIND/SR/OTH/25015 | M18: 45911 | N18: 850000 | O18: January | P18: March | Q18: 0.5 | V18: =Table62689345[[#This Row],[Offer Value]]-Table62689345[[#This Row],[PO Value]] -> 850000
A19: 12 | B19: 45922 | C19: Kirloskar Ebara Pumps LTD | D19: Kirloskarwadi | E19: stores | F19: sachin mali | G19: 7796670030 | H19: SACHIN.MALI@kepl.in.net | I19: 05007988/001 | J19: SPP | K19: Yes | L19: KXIND/W/YD/SPP/25064 | M19: 45922 | N19: 795668 | O19: January | P19: March | Q19: 0.5 | V19: =Table62689345[[#This Row],[Offer Value]]-Table62689345[[#This Row],[PO Value]] -> 795668
A20: 13 | B20: 45705 | C20: Bajaj Auto Ltd | D20: Pune | E20: Eng.stores | F20: Rajkumar Ajabe | G20: 9503050525 | H20: rrajabe@bajajauto.co.in | I20: 00011128/004 | J20: SPP | K20: Yes | L20: KXIND/W/YD/MLU/25011 | M20: 45687 | N20: 558580 | O20: January | P20: January | Q20: 0.5 | V20: =Table62689345[[#This Row],[Offer Value]]-Table62689345[[#This Row],[PO Value]] -> 558580
A21: 15 | B21: 45930 | C21: Tata Motors LTD | D21: Pune | E21: D blockstore | F21: Jyoti Avhad | G21: 8237003520 | H21: jyoti.avhad@tatamotors.com | I21: 16002093/001 | J21: Contract | K21: No | L21: KXIND/W/YD/MC/25077 | M21: 45929 | N21: 90000 | O21: January | P21: January | Q21: 0.5 | V21: =Table62689345[[#This Row],[Offer Value]]-Table62689345[[#This Row],[PO Value]] -> 90000
A22: 16 | B22: 45930 | C22: Tata Motors LTD | D22: Pune | E22: D blockstore | F22: Jyoti Avhad | G22: 8237003521 | H22: jyoti.avhad@tatamotors.com | I22: 16002093/002 | J22: Contract | K22: No | L22: KXIND/W/YD/MC/25077 | M22: 45929 | N22: 90000 | O22: January | P22: January | Q22: 0.5 | V22: =Table62689345[[#This Row],[Offer Value]]-Table62689345[[#This Row],[PO Value]] -> 90000
A23: 17 | B23: 45961 | C23: ITC Ltd | D23: Pune | E23: Engineering stores | F23: Navanath Ekatpure | G23: 9730478741 | H23: navanath.ekatpure@itc.in | I23: 09006715/001 | J23: SPP | K23: Yes | L23: KXIND/W/YD/SPP/25075 | M23: 45926 | N23: 79812 | O23: January | P23: January | Q23: 0.5 | V23: =Table62689345[[#This Row],[Offer Value]]-Table62689345[[#This Row],[PO Value]] -> 79812
A24: 18 | B24: 45981 | C24: Kirloskar Oil Engine LTD | D24: kagal | E24: Stores | F24: Ganesh Jagtap | G24: 9881734612 | H24: ganesh.jagtap@kirloskar.com | I24: 07010686/001 | J24: SPP | K24: Yes | L24: KXIND/W/YD/SPP/25080 | M24: 45979 | N24: 2064784 | O24: January | P24: March | Q24: 0.3 | V24: =Table62689345[[#This Row],[Offer Value]]-Table62689345[[#This Row],[PO Value]] -> 2064784
A25: 19 | B25: 45985 | C25: Tata motors passenger vehicles Limted (Tata Motors Ltd) | D25: Pune | E25: Logistics | F25: Sujit Kadam | G25: 7276004071 | H25: sujit.kadam@tatamotors.com | I25: 06009440/004 | J25: Upgradekit | K25: Yes | L25: KXIND/W/YD/SPP/25082 | M25: 45982 | N25: 3402210 | O25: January | P25: March | Q25: 0.2 | V25: =Table62689345[[#This Row],[Offer Value]]-Table62689345[[#This Row],[PO Value]] -> 3402210
A26: 20 | B26: 45985 | C26: Tata motors passenger vehicles Limted (Tata Motors Ltd) | D26: Pune | E26: Logistics | F26: Sujit kadam | G26: 7276004071 | H26: sujit.kadam@tatamotors.com | I26: 06009440/004 | J26: Retrofitkit | K26: Yes | L26: KXIND/W/YD/SPP/25083 | M26: 45982 | N26: 1248375 | O26: January | P26: March | Q26: 0.2 | V26: =Table62689345[[#This Row],[Offer Value]]-Table62689345[[#This Row],[PO Value]] -> 1248375
A27: 21 | B27: 45999 | C27: Fiat india Automobiles Pvt. LTD | D27: Pune | E27: stores | F27: Ajinkya Suryavanshi | G27: 7875555910 | H27: Ajinkya.Suryavanshi@fiapl.com | I27: 10005770/001 | J27: Upgradekit | K27: Yes | L27: KXIND/W/SPP/YD/25086 | M27: 45999 | N27: 1144969 | O27: January | P27: February | Q27: 0.2 | V27: =Table62689345[[#This Row],[Offer Value]]-Table62689345[[#This Row],[PO Value]] -> 1144969
A28: 22 | B28: 45999 | C28: Tata Motors LTD | D28: Pune | E28: ERC div | F28: Gaurav Bajpai | G28: 9604125704 | H28: gaurav.bajpai@tatamotors.com | I28: 12001954/001 | J28: SPP | K28: Yes | L28: KXIND/W/SPP/YD/25088 | M28: 45999 | N28: 128350 | O28: January | P28: January | Q28: 0.2 | V28: =Table62689345[[#This Row],[Offer Value]]-Table62689345[[#This Row],[PO Value]] -> 128350
A29: 23 | B29: 45999 | C29: Tetra Pak India Pvt Ltd | D29: Pune | E29: Stores | F29: Pranjal Dhok | G29: 88888 13957 | H29: Pranjal.Dhok@tetrapak.com | I29: 07009761/001 | J29: Relocation | K29: No | L29: KRIND/W/RE/25090 | M29: 45995 | N29: 320000 | O29: January | P29: January | Q29: 0.9 | R29: 700683864 | S29: 9-12-12025 | T29: 320000 | U29: January | V29: =Table62689345[[#This Row],[Offer Value]]-Table62689345[[#This Row],[PO Value]] -> 0
A30: 24 | B30: 45841 | C30: Bajaj Auto Ltd | D30: Pune | E30: Ele.veh | F30: Gopal Adhao | G30: 9860955055 | H30: gsadhao@bajajauto.co.in | I30: 18001595/001 | J30: Relocation | K30: No | L30: KRIND/W/YD/RE/25052 | M30: 45834 | N30: 350000 | O30: January | P30: January | Q30: 0.5 | R30: 3110015532 | S30: 26.07.2025 | T30: 350000 | U30: January | V30: =Table62689345[[#This Row],[Offer Value]]-Table62689345[[#This Row],[PO Value]] -> 0
A31: 25 | B31: 46035 | C31: Skoda Auto Volkswagen India Pvt Ltd | D31: Pune | E31: stores | F31: Pranav shinde | G31: 7744051513 | H31: pranav.shinde1@skoda-vw.co.in | I31: 102008505 | J31: Contract | K31: No | L31: KXIND/W/MC/YD/26006 | M31: 46035 | N31: 127200 | O31: January | P31: January | Q31: 0.5 | V31: =Table62689345[[#This Row],[Offer Value]]-Table62689345[[#This Row],[PO Value]] -> 127200
A32: 26 | C32: Skoda Auto Volkswagen India Pvt Ltd | D32: Pune | E32: stores | F32: Pranav shinde | G32: 7744051513 | H32: pranav.shinde1@skoda-vw.co.in | I32: 102008506 | J32: Contract | K32: No | L32: KXIND/W/MC/YD/26006 | M32: 46035 | N32: 127200 | O32: January | P32: January | Q32: 0.5 | V32: =Table62689345[[#This Row],[Offer Value]]-Table62689345[[#This Row],[PO Value]] -> 127200
A33: 27 | C33: Skoda Auto Volkswagen India Pvt Ltd | D33: Pune | E33: stores | F33: Pranav shinde | G33: 7744051513 | H33: pranav.shinde1@skoda-vw.co.in | I33: 102008507 | J33: Contract | K33: No | L33: KXIND/W/MC/YD/26006 | M33: 46035 | N33: 127200 | O33: January | P33: January | Q33: 0.5 | V33: =Table62689345[[#This Row],[Offer Value]]-Table62689345[[#This Row],[PO Value]] -> 127200
A34: 28 | C34: Skoda Auto Volkswagen India Pvt Ltd | D34: Pune | E34: stores | F34: Pranav shinde | G34: 7744051513 | H34: pranav.shinde1@skoda-vw.co.in | I34: 102008508 | J34: Contract | K34: No | L34: KXIND/W/MC/YD/26006 | M34: 46035 | N34: 127200 | O34: January | P34: January | Q34: 0.5 | V34: =Table62689345[[#This Row],[Offer Value]]-Table62689345[[#This Row],[PO Value]] -> 127200
A35: 29 | C35: Skoda Auto Volkswagen India Pvt Ltd | D35: Pune | E35: stores | F35: Pranav shinde | G35: 7744051513 | H35: pranav.shinde1@skoda-vw.co.in | I35: 102008509 | J35: Contract | K35: No | L35: KXIND/W/MC/YD/26006 | M35: 46035 | N35: 127200 | O35: January | P35: January | Q35: 0.5 | V35: =Table62689345[[#This Row],[Offer Value]]-Table62689345[[#This Row],[PO Value]] -> 127200
A36: 30 | C36: Skoda Auto Volkswagen India Pvt Ltd | D36: Pune | E36: stores | F36: Pranav shinde | G36: 7744051513 | H36: pranav.shinde1@skoda-vw.co.in | I36: 102010375 | J36: Contract | K36: No | L36: KXIND/W/MC/YD/26006 | M36: 46035 | N36: 127200 | O36: January | P36: January | Q36: 0.5 | V36: =Table62689345[[#This Row],[Offer Value]]-Table62689345[[#This Row],[PO Value]] -> 127200
A37: 31 | C37: Skoda Auto Volkswagen India Pvt Ltd | D37: Pune | E37: stores | F37: Pranav shinde | G37: 7744051513 | H37: pranav.shinde1@skoda-vw.co.in | I37: 102010376 | J37: Contract | K37: No | L37: KXIND/W/MC/YD/26006 | M37: 46035 | N37: 127200 | O37: January | P37: January | Q37: 0.5 | V37: =Table62689345[[#This Row],[Offer Value]]-Table62689345[[#This Row],[PO Value]] -> 127200
A38: 32 | B38: 46035 | C38: Tetra Pak India Pvt Ltd | D38: Pune | E38: Spare stores | F38: Vivek Kamya | G38: 9850806974 | H38: Vivek.Kyama@tetrapak.com | I38: 07009761/001 | J38: Contract | K38: No | L38: KXIND/W/YD/MC/26004 | M38: 46029 | N38: 96000 | O38: January | P38: January | Q38: 0.8 | V38: =Table62689345[[#This Row],[Offer Value]]-Table62689345[[#This Row],[PO Value]] -> 96000
A39: 33 | B39: 46035 | C39: Klug avalon mechatronics | D39: Pune | E39: stores | F39: N.Patil | G39: 9271117805 | H39: rms@klugavalon.com | I39: 16007512/001 | J39: Contract | K39: No | L39: KXIND/W/YD/MC/26002 | M39: 46029 | N39: 60000 | O39: January | P39: February | Q39: 0.8 | V39: =Table62689345[[#This Row],[Offer Value]]-Table62689345[[#This Row],[PO Value]] -> 60000
A40: 34 | B40: 46035 | C40: Bosch Chassis Systems India Ltd | D40: Pune | E40: maintenance store | F40: Pratap Jagdale | G40: 9970010738 | H40: Pratap.Jagadale@in.bosch.com | I40: 19004857/001 | J40: Contract | K40: No | L40: KXIND/W/YD/MC/26003 | M40: 46017 | N40: 74500 | O40: January | P40: February | Q40: 1 | V40: =Table62689345[[#This Row],[Offer Value]]-Table62689345[[#This Row],[PO Value]] -> 74500
A41: 35 | B41: 46035 | C41: Merck Life Science Pvt Ltd | D41: Mumbai | E41: stores | F41: Kalpesh Patil | G41: 9762817803 | H41: Kalpesh.patil@merckgroup.com | I41: 23004830/001 | J41: Contract | K41: Yes | L41: KXIND/W/YD/MC/26001 | M41: 46017 | N41: 67500 | O41: January | P41: February | Q41: 0.4 | V41: =Table62689345[[#This Row],[Offer Value]]-Table62689345[[#This Row],[PO Value]] -> 67500
...

Sheet Ashraf
A2: KARDEX INDIA - LIVE OFFER FUNEL - ASHRAF - WEST
A3: Total Offers | B3: =COUNTA(B8:B1436) -> 41 | C3: Month | D3: Offers Total | E3: Order received | F3: Forecast | G3: Forecast- Po Received | H3: Month | I3: Offers Total | J3: Order received | K3: Forecast | L3: Forecast- Po Received | M3: Month | N3: Offers Total | O3: Order received | P3: Forecast | Q3: Forecast- Po Received | R3: Month | S3: Offers Total | T3: Order received | U3: Forecast | V3: Forecast- Po Received | W3: Total Open Funnel | X3: =SUM(V21:V2006) -> 24399164
C4: January | D4: =SUMIF($O$7:$O$405,"January",$N$7:$N$405) -> 28089330 | E4: =SUMIF($U$7:$U$405,"January",$T$7:$T$405) -> 3673246 | F4: =SUMIF($P$7:$P$424,"January",$N$7:$N$424) -> 8052443 | G4: =F4-E4 -> 4379197 | H4: April | I4: =SUMIF($O$7:$O$405,"April",$N$7:$N$405) -> 0 | J4: =SUMIF($U$7:$U$405,"April",$T$7:$T$405) -> 0 | K4: =SUMIF($P$7:$P$424,"April",$N$7:$N$424) -> 0 | L4: =K4-J4 -> 0 | M4: July | N4: =SUMIF($O$7:$O$405,"July",$N$7:$N$405) -> 0 | O4: =SUMIF($U$7:$U$405,"July",$T$7:$T$405) -> 0 | P4: =SUMIF($P$7:$P$424,"July",$N$7:$N$424) -> 0 | Q4: =P4-O4 -> 0 | R4: October | S4: =SUMIF($O$7:$O$405,"October",$N$7:$N$405) -> 0 | T4: =SUMIF($U$7:$U$405,"October",$T$7:$T$405) -> 0 | U4: =SUMIF($P$7:$P$424,"October",$N$7:$N$424) -> 0 | V4: =U4-T4 -> 0
C5: February | D5: =SUMIF($O$7:$O$405,"February",$N$7:$N$405) -> 0 | E5: =SUMIF($U$7:$U$405,"February",$T$7:$T$405) -> 0 | F5: =SUMIF($P$7:$P$424,"February",$N$7:$N$424) -> 2004278 | G5: =F5-E5 -> 2004278 | H5: May | I5: =SUMIF($O$7:$O$405,"May",$N$7:$N$405) -> 0 | J5: =SUMIF($U$7:$U$405,"May",$T$7:$T$405) -> 0 | K5: =SUMIF($P$7:$P$424,"May",$N$7:$N$424) -> 0 | L5: =K5-J5 -> 0 | M5: August | N5: =SUMIF($O$7:$O$405,"August",$N$7:$N$405) -> 0 | O5: =SUMIF($U$7:$U$405,"August",$T$7:$T$405) -> 0 | P5: =SUMIF($P$7:$P$424,"August",$N$7:$N$424) -> 0 | Q5: =P5-O5 -> 0 | R5: November | S5: =SUMIF($O$7:$O$405,"November",$N$7:$N$405) -> 0 | T5: =SUMIF($U$7:$U$405,"November",$T$7:$T$405) -> 0 | U5: =SUMIF($P$7:$P$424,"November",$N$7:$N$424) -> 0 | V5: =U5-T5 -> 0
C6: March | D6: =SUMIF($O$7:$O$405,"March",$N$7:$N$405) -> 0 | E6: =SUMIF($U$7:$U$405,"March",$T$7:$T$405) -> 0 | F6: =SUMIF($P$7:$P$424,"March",$N$7:$N$424) -> 18032609 | G6: =F6-E6 -> 18032609 | H6: June | I6: =SUMIF($O$7:$O$405,"June",$N$7:$N$405) -> 0 | J6: =SUMIF($U$7:$U$405,"June",$T$7:$T$405) -> 0 | K6: =SUMIF($P$7:$P$424,"June",$N$7:$N$424) -> 0 | L6: =K6-J6 -> 0 | M6: September | N6: =SUMIF($O$7:$O$405,"September",$N$7:$N$405) -> 0 | O6: =SUMIF($U$7:$U$405,"September",$T$7:$T$405) -> 0 | P6: =SUMIF($P$7:$P$424,"September",$N$7:$N$424) -> 0 | Q6: =P6-O6 -> 0 | R6: December | S6: =SUMIF($O$7:$O$405,"December",$N$7:$N$405) -> 0 | T6: =SUMIF($U$7:$U$405,"December",$T$7:$T$405) -> 0 | U6: =SUMIF($P$7:$P$424,"December",$N$7:$N$424) -> 0 | V6: =U6-T6 -> 0
A7: SL | B7: Reg Date | C7: Company | D7: Location | E7: Department | F7: Contact Person Name | G7: Contact Number | H7: E-Mail ID | I7: Machine Serial Number | J7: Product Type | K7: Lead | L7: Offer Reference Number | M7: Offer Reference Date | N7: Offer Value | O7: Offer Month | P7: PO Expected Month | Q7: Probabality in Percentage | R7: PO Number | S7: PO Date | T7: PO Value | U7: PO Received Month | V7: Open Funnel | W7: Remarks | X7: Status | Y7: Booking Date in SAP B1 | Z7: Offer Entered in CRM | AA7: Offer Closed in CRM
A8: 1 | B8: 45418 | C8: Siemens Ltd. | D8: Mumbai | E8: stores | F8: Nilesh Tandale | G8: 9920190055 | H8: nilesh.tandle@siemens.com | I8: 06008965/001 | J8: Relocation | K8: No | L8: KAR/IND/RE/AB/004 | M8: 45418 | N8: 730000 | O8: January | P8: January | Q8: 1 | R8: 4513049404 | S8: 45531 | T8: 718000 | U8: January | V8: =N8-T8 -> 12000
A9: 2 | B9: 45694 | C9: Kirloskar brothers LTD | D9: Kirloskawadi | E9: LPD | F9: Amit Gotkhindikar | G9: 8459230159 | H9: amit.gotkhindikar@kbl.co.in | I9: 11006582/001 | J9: Contract | K9: NO | L9: KAR/IND/AB/AMC/240021 | M9: 45695 | N9: 82000 | O9: January | P9: January | Q9: 1 | R9: 1600034060 | S9: 45867 | T9: 79540 | U9: January | V9: =N9-T9 -> 2460
A10: 3 | C10: Kirloskar brothers LTD | D10: Kirloskawadi | E10: SMPD | F10: Amit Gotkhindikar | G10: 8459230159 | H10: amit.gotkhindikar@kbl.co.in | I10: 11006583/001 | J10: Contract | K10: NO | L10: KAR/IND/AB/AMC/240021 | M10: 45695 | N10: 82000 | O10: January | P10: January | Q10: 1 | R10: 1600034060 | S10: 45867 | T10: 79540 | U10: January | V10: =N10-T10 -> 2460
A11: 4 | B11: 45890 | C11: Danfoss Power solutions Pvt.ltd. | D11: Pune | E11: Stores | F11: Ramesh Kumbhar | G11: 7447765126 | H11: rkumbhar@danfoss.com | I11: 23003615/001 | J11: Contract | K11: Yes | L11: KRIND/W/MC/AB/NM/25004 | M11: 45890 | N11: 55000 | O11: January | P11: January | Q11: 1 | R11: 4509091008 | S11: 45909 | T11: 55000 | U11: January | V11: =N11-T11 -> 0
A12: 5 | B12: 45890 | C12: Danfoss Power solutions Pvt.ltd. | D12: Pune | E12: Stores | F12: Ramesh Kumbhar | G12: 7447765126 | H12: rkumbhar@danfoss.com | I12: 23003615/001 | J12: Software | K12: Yes | L12: KRIND/W/MC/AB/NM/25004 | M12: 45890 | N12: 32000 | O12: January | P12: January | Q12: 1 | R12: 4509091008 | S12: 45909 | T12: 32000 | U12: January | V12: =N12-T12 -> 0
A13: 6 | B13: 45898 | C13: Firmenich Aerometics I Pvt.ltd. | D13: Mumbai | E13: Ingredients | F13: Shalaka Aparaj | G13: 9136424956 | H13: shalaka.aparaj@dsm-firmenich.com | I13: 18007782/001 | J13: Contract | K13: No | L13: KRIND/W/MC/AB/250030 | M13: 45898 | N13: 58000 | O13: January | P13: January | Q13: 1 | R13: 3800035834 | S13: 45926 | T13: 58000 | U13: January | V13: =N13-T13 -> 0
A14: 7 | B14: 8/29/2025 | C14: Firmenich Aerometics I Pvt.ltd. | D14: Mumbai | E14: Perfumes | F14: Sujay Pujari | G14: 9892946492 | H14: sujay.pujari@dsm-firmenich.com | I14: 18007779/001 | J14: Contract | K14: No | L14: KXIND/W/MC/AB250029 | M14: 8/29/2025 | N14: 58000 | O14: January | P14: January | Q14: 1 | R14: 3800044370 | S14: 45727 | T14: 58000 | U14: January | V14: =N14-T14 -> 0
A15: 8 | C15: Firmenich Aerometics I Pvt.ltd. | D15: Mumbai | E15: Perfumes | F15: Sujay Pujari | G15: 9892946492 | H15: sujay.pujari@dsm-firmenich.com | I15: 18007777/001 | J15: Contract | K15: No | L15: KXIND/W/MC/AB250029 | M15: 8/29/2025 | N15: 58000 | O15: January | P15: January | Q15: 1 | R15: 3800044370 | S15: 45727 | T15: 58000 | U15: January | V15: =N15-T15 -> 0
A16: 9 | C16: Firmenich Aerometics I Pvt.ltd. | D16: Mumbai | E16: Perfumes | F16: Sujay Pujari | G16: 9892946492 | H16: sujay.pujari@dsm-firmenich.com | I16: 18007777/001 | J16: Software | K16: No | L16: KXIND/W/MC/AB250029 | M16: 8/29/2025 | N16: 32000 | O16: January | P16: January | Q16: 1 | R16: 3800044370 | S16: 45727 | T16: 32000 | U16: January | V16: =N16-T16 -> 0
A17: 10 | B17: 45957 | C17: KSPG Automotive India PVT LTD | D17: Pune | E17: Tool Room | F17: Kanchan Patil | G17: 9049009865 | H17: kanchan.patil@in.rheinmetall.com | I17: 18008781/001 | J17: Contract | K17: NO | L17: KXIND/W/MC/AB25031 | M17: 45957 | N17: 70000 | O17: January | P17: January | Q17: 1 | R17: IN4 / 1443021494 | S17: 45964 | T17: 70000 | U17: January | V17: =N17-T17 -> 0
A18: 11 | C18: KSPG Automotive India PVT LTD | D18: Pune | E18: Tool Room | F18: Kanchan Patil | G18: 9049009866 | H18: kanchan.patil@in.rheinmetall.com | I18: 19002522/001 | J18: Contract | K18: NO | L18: KXIND/W/MC/AB25031 | M18: 45957 | N18: 70000 | O18: January | P18: January | Q18: 1 | R18: IN4 / 1443021495 | S18: 45965 | T18: 70000 | U18: January | V18: =N18-T18 -> 0
A19: 12 | B19: 45957 | C19: KSPG Automotive India PVT LTD | D19: Pune | E19: stores | F19: Bharat Markad | G19: 9975371327 | H19: Bharat.Markad@in.rheinmetall.com | I19: 11002648/004 | J19: Contract | K19: NO | L19: REPEAT PO | M19: 45957 | N19: 45000 | O19: January | P19: January | Q19: 1 | R19: 4500088897 | S19: 45958 | T19: 45000 | U19: January | V19: =N19-T19 -> 0
A20: 13 | C20: KSPG Automotive India PVT LTD | D20: Pune | E20: stores | F20: Bharat Markad | G20: 9975371327 | H20: Bharat.Markad@in.rheinmetall.com | I20: 11002654/001 | J20: Contract | K20: NO | L20: REPEAT PO | M20: 45957 | N20: 45000 | O20: January | P20: January | Q20: 1 | R20: 4500088897 | S20: 45958 | T20: 45000 | U20: January | V20: =N20-T20 -> 0
A21: 14 | C21: KSPG Automotive India PVT LTD | D21: Pune | E21: stores | F21: Bharat Markad | G21: 9975371327 | H21: Bharat.Markad@in.rheinmetall.com | I21: 15001232/001 | J21: Contract | K21: NO | L21: REPEAT PO | M21: 45957 | N21: 45000 | O21: January | P21: February | Q21: 0.5 | V21: =N21-T21 -> 45000
A22: 15 | C22: KSPG Automotive India PVT LTD | D22: Pune | E22: stores | F22: Bharat Markad | G22: 9975371327 | H22: Bharat.Markad@in.rheinmetall.com | I22: 15001233/001 | J22: Contract | K22: NO | L22: REPEAT PO | M22: 45957 | N22: 45000 | O22: January | P22: February | Q22: 0.5 | V22: =N22-T22 -> 45000
A23: 16 | C23: KSPG Automotive India PVT LTD | D23: Pune | E23: stores | F23: Bharat Markad | G23: 9975371327 | H23: Bharat.Markad@in.rheinmetall.com | I23: 15001234/001 | J23: Contract | K23: NO | L23: REPEAT PO | M23: 45957 | N23: 45000 | O23: January | P23: January | Q23: 1 | R23: 4500089764 | S23: 46006 | T23: 45000 | U23: January | V23: =N23-T23 -> 0
A24: 17 | B24: 45957 | C24: Bharat petrolium corporation Ltd. | D24: Mumbai | E24: warehouse | F24: Niral K | G24: 8454998540 | H24: niralkhalkho@bharatpetroleum.in | I24: 06005849/001 | J24: Upgradekit | K24: YES | L24: KRIND/W/SPP/AB25004 | M24: 45966 | N24: 1180061 | O24: January | P24: January | Q24: 1 | R24: 4511334164 | S24: 46007 | T24: 1180061 | U24: January | V24: =N24-T24 -> 0
A25: 18 | B25: 45987 | C25: Cummins India Ltd | D25: Pune | E25: NHNT | F25: Sopan Jadhav | H25: sopan.jadhav@cummins.com | I25: 00009908/005 | J25: SPP | K25: YES | L25: KRIND/W/SPP/AB25019 | M25: 45859 | N25: 45000 | O25: January | P25: January | Q25: 1 | R25: IND8333007 | S25: 46006 | T25: 34920 | U25: January | V25: =N25-T25 -> 10080
A26: 19 | B26: 45812 | C26: Alfa Laval India LTD | D26: Pune | E26: DLC | F26: Ranjit Shinde | G26: 7045525011 | H26: ranjit.shinde@alfalaval.com | I26: 07010871/001 | J26: MidlifeUpgrade | K26: NO | L26: KRIND/W/SPP/AB/25015 | M26: 45812 | N26: 550271 | O26: January | P26: March | Q26: 0.5 | V26: =N26-T26 -> 550271
A27: 20 | B27: 45840 | C27: Sedmac Mechatronics Pvt.Ltd. | D27: Pune | E27: Stores | F27: Amol Inamdar | G27: 9689900920 | H27: amol.inamdar@sedemac.com | I27: 18008976/001 | J27: Retrofitkit | K27: YES | L27: KRIND/W/RF/AB26008 | M27: 45840 | N27: 13500000 | O27: January | P27: March | Q27: 0.5 | V27: =N27-T27 -> 13500000
A28: 21 | B28: 45922 | C28: Subros Ltd. | D28: Pune | E28: Stores | F28: shahrukh Kazi | G28: 8888980936 | H28: shaharukh.kazi@subros.com | I28: 12004504/001 | J28: Upgradekit | K28: YES | L28: KRIND/W/SPP/AB250027 | M28: 45922 | N28: 1221242 | O28: January | P28: March | Q28: 0.5 | V28: =N28-T28 -> 1221242
A29: 22 | B29: 45929 | C29: Wirtgen India Pvt.Ltd. | D29: Pune | E29: Kleenman | F29: Sagar Brijpuriya | G29: 8956509715 | H29: sagar.brijpuriya@wirtgen-group.com | I29: 16004741/002 | J29: Contract | K29: No | L29: KXIND/W/MC/AB/25028 | M29: 45898 | N29: 65000 | O29: January | P29: January | Q29: 0.5 | V29: =N29-T29 -> 65000
A30: 23 | C30: Wirtgen India Pvt.Ltd. | D30: Pune | E30: Kleenman | F30: Sagar Brijpuriya | G30: 8956509715 | H30: sagar.brijpuriya@wirtgen-group.com | I30: 16004741/002 | J30: Contract | K30: No | L30: KXIND/W/MC/AB/25028 | M30: 45898 | N30: 65000 | O30: January | P30: January | Q30: 0.5 | V30: =N30-T30 -> 65000
A31: 24 | B31: 46611 | C31: Kalyani technoforge Ltd. | D31: Ambethan | E31: Stores | F31: Rahul Javane | H31: rahul.javane@kalyanitechnoforge.com | J31: Contract | K31: Yes | L31: KRIND/W/MC/AB/NM/25003 | M31: 45881 | N31: 75000 | O31: January | P31: February | Q31: 0.5 | V31: =N31-T31 -> 75000
A32: 25 | B32: 45930 | C32: Alfa Laval India LTD | D32: Pune | E32: HSS | F32: Shashikant Jagtap | G32: 8605611200 | H32: shashikant.jagtap@alfalaval.com | I32: 05008611/001 | J32: SPP | K32: Yes | L32: KRIND/W/SPP/AB25030 | M32: 45930 | N32: 386482 | O32: January | P32: February | Q32: 0.5 | V32: =N32-T32 -> 386482
A33: 26 | B33: 45940 | C33: Bharat Electronics Ltd | D33: Pune | E33: Stores | F33: Vilas Khade | G33: 2022903115 | H33: vilaskhade@bel.co.in | I33: 04002775/002 | J33: SPP | K33: Yes | L33: KRIND/W/SPP/AB25037 | M33: 45940 | N33: 606100 | O33: January | P33: January | Q33: 0.5 | V33: =N33-T33 -> 606100
A34: 27 | B34: 45955 | C34: Knorr-Bremse Systems for Commercial Vehicles | D34: Pune | E34: Stores | F34: Prakash Parihar | G34: 9907829409 | H34: prakashsingh.parihar@knorr-bremse.com | I34: 24000529/001 | J34: SPP | K34: Yes | L34: KRIND/W/SPP/AB25041 | M34: 45955 | N34: 611382 | O34: January | P34: January | Q34: 0.5 | V34: =N34-T34 -> 611382
A35: 28 | B35: 45957 | C35: Knorr-Bremse Systems for Commercial Vehicles | D35: Pune | E35: Stores | F35: Prakash Parihar | G35: 9907829409 | H35: prakashsingh.parihar@knorr-bremse.com | I35: 24000529/001 | J35: Contract | K35: Yes | L35: KXIND/S/AB/SC/25001 | M35: 45957 | N35: 42000 | O35: January | P35: January | Q35: 0.5 | V35: =N35-T35 -> 42000
A36: 29 | B36: 45959 | C36: KSPG Automotive India PVT LTD | D36: Pune | E36: stores | F36: Bharat Markad | G36: 9975371327 | H36: bharat.markad@in.kspg.com | I36: 15001233/001 | J36: SPP | K36: Yes | L36: KRIND/W/SPP/AB25043 | M36: 45959 | N36: 409602 | O36: January | P36: February | Q36: 0.5 | V36: =N36-T36 -> 409602
A37: 30 | B37: 45987 | C37: Cummins India Ltd | D37: Pune | E37: EM | F37: Kiran Dole | H37: kiran.dole@cummins.com | I37: 00009908/005 | J37: SPP | K37: yes | L37: KRIND/W/SPP/AB25044 | M37: 45987 | N37: 975900 | O37: January | P37: January | Q37: 1 | R37: IND8331361 | S37: 46003 | T37: 365690 | U37: January | V37: =N37-T37 -> 610210
A38: 31 | B38: 45989 | C38: Bharat Electronics Ltd | D38: Navi Mumbai | E38: stores | F38: Vishal Kulkarni | G38: 9766935985 | H38: vishal.kulkarni@bel.co.in | I38: 14000071/001 | J38: SPP | K38: Yes | L38: KRIND/W/SPP/AB25045 | M38: 45989 | N38: 350860 | O38: January | P38: February | Q38: 0.5 | V38: =N38-T38 -> 350860
A39: 32 | B39: 46002 | C39: Mahindra & Mahindra LTD | D39: Mumbai | E39: FED | F39: Atul Gade | G39: 9923496979 | H39: GADE.ATUL@mahindra.com | I39: 11010119/001 | J39: SPP | K39: YES | L39: KRIND/W/SPP/AB250046 | M39: 46002 | N39: 561709 | O39: January | P39: March | Q39: 0.5 | V39: =N39-T39 -> 561709
A40: 33 | B40: 45999 | C40: Tata Cummins Pvt Ltd | D40: phaltan | E40: stores | F40: vijay Pawar | G40: 7796646965 | H40: vijay.pawar@cummins.com | I40: 14006903/001 | J40: SPP | K40: YES | L40: KRIND/W/SPP/AB25047 | M40: 45999 | N40: 484800 | O40: January | P40: march | Q40: 0.5 | V40: =N40-T40 -> 484800
A41: 34 | B41: 46027 | C41: KSB Pumps LTD | D41: shirwal | E41: Stores | F41: Sachine Pawar | G41: 9822412607 | H41: sachin.pawar@ksb.com | I41: 02002336/002 | J41: SPP | K41: YES | L41: KRIND/W/SPP/AB/26001 | M41: 46027 | N41: 250000 | O41: January | P41: February | Q41: 0.5 | V41: =N41-T41 -> 250000
...

Sheet Rahul
A2: KARDEX INDIA - LIVE OFFER FUNEL - RAHUL - WEST
A3: Total Offers | B3: =COUNTA(B8:B1430) -> 35 | C3: Month | D3: Offers Total | E3: Order received | F3: Forecast | G3: Forecast- Po Received | H3: Month | I3: Offers Total | J3: Order received | K3: Forecast | L3: Forecast- Po Received | M3: Month | N3: Offers Total | O3: Order received | P3: Forecast | Q3: Forecast- Po Received | R3: Month | S3: Offers Total | T3: Order received | U3: Forecast | V3: Forecast- Po Received | W3: Total Open Funnel | X3: =SUM(V8:V2000) -> 10201166
C4: January | D4: =SUMIF($O$7:$O$399,"January",$N$7:$N$399) -> 15954234 | E4: =SUMIF($U$7:$U$399,"January",$T$7:$T$399) -> 7830545 | F4: =SUMIF($P$7:$P$418,"January",$N$7:$N$418) -> 7319551 | G4: =F4-E4 -> -510994 | H4: April | I4: =SUMIF($O$7:$O$399,"April",$N$7:$N$399) -> 0 | J4: =SUMIF($U$7:$U$399,"April",$T$7:$T$399) -> 0 | K4: =SUMIF($P$7:$P$418,"April",$N$7:$N$418) -> 443800 | L4: =K4-J4 -> 443800 | M4: July | N4: =SUMIF($O$7:$O$399,"July",$N$7:$N$399) -> 0 | O4: =SUMIF($U$7:$U$399,"July",$T$7:$T$399) -> 0 | P4: =SUMIF($P$7:$P$418,"July",$N$7:$N$418) -> 0 | Q4: =P4-O4 -> 0 | R4: October | S4: =SUMIF($O$7:$O$399,"October",$N$7:$N$399) -> 0 | T4: =SUMIF($U$7:$U$399,"October",$T$7:$T$399) -> 0 | U4: =SUMIF($P$7:$P$418,"October",$N$7:$N$418) -> 0 | V4: =U4-T4 -> 0
C5: February | D5: =SUMIF($O$7:$O$399,"February",$N$7:$N$399) -> 2744733 | E5: =SUMIF($U$7:$U$399,"February",$T$7:$T$399) -> 27360 | F5: =SUMIF($P$7:$P$418,"February",$N$7:$N$418) -> 5546963 | G5: =F5-E5 -> 5519603 | H5: May | I5: =SUMIF($O$7:$O$399,"May",$N$7:$N$399) -> 0 | J5: =SUMIF($U$7:$U$399,"May",$T$7:$T$399) -> 0 | K5: =SUMIF($P$7:$P$418,"May",$N$7:$N$418) -> 2484976 | L5: =K5-J5 -> 2484976 | M5: August | N5: =SUMIF($O$7:$O$399,"August",$N$7:$N$399) -> 0 | O5: =SUMIF($U$7:$U$399,"August",$T$7:$T$399) -> 0 | P5: =SUMIF($P$7:$P$418,"August",$N$7:$N$418) -> 0 | Q5: =P5-O5 -> 0 | R5: November | S5: =SUMIF($O$7:$O$399,"November",$N$7:$N$399) -> 0 | T5: =SUMIF($U$7:$U$399,"November",$T$7:$T$399) -> 0 | U5: =SUMIF($P$7:$P$418,"November",$N$7:$N$418) -> 0 | V5: =U5-T5 -> 0
C6: March | D6: =SUMIF($O$7:$O$399,"March",$N$7:$N$399) -> 0 | E6: =SUMIF($U$7:$U$399,"March",$T$7:$T$399) -> 0 | F6: =SUMIF($P$7:$P$418,"March",$N$7:$N$418) -> 2251617 | G6: =F6-E6 -> 2251617 | H6: June | I6: =SUMIF($O$7:$O$399,"June",$N$7:$N$399) -> 0 | J6: =SUMIF($U$7:$U$399,"June",$T$7:$T$399) -> 0 | K6: =SUMIF($P$7:$P$418,"June",$N$7:$N$418) -> 0 | L6: =K6-J6 -> 0 | M6: September | N6: =SUMIF($O$7:$O$399,"September",$N$7:$N$399) -> 0 | O6: =SUMIF($U$7:$U$399,"September",$T$7:$T$399) -> 0 | P6: =SUMIF($P$7:$P$418,"September",$N$7:$N$418) -> 0 | Q6: =P6-O6 -> 0 | R6: December | S6: =SUMIF($O$7:$O$399,"December",$N$7:$N$399) -> 0 | T6: =SUMIF($U$7:$U$399,"December",$T$7:$T$399) -> 0 | U6: =SUMIF($P$7:$P$418,"December",$N$7:$N$418) -> 652060 | V6: =U6-T6 -> 652060
A7: SL | B7: Reg Date | C7: Company | D7: Location | E7: Department | F7: Contact Person Name | G7: Contact Number | H7: E-Mail ID | I7: Machine Serial Number | J7: Product Type | K7: Lead | L7: Offer Reference Number | M7: Offer Reference Date | N7: Offer Value | O7: Offer Month | P7: PO Expected Month | Q7: Probabality in Percentage | R7: PO Number | S7: PO Date | T7: PO Value | U7: PO Received Month | V7: Open Funnel | W7: Remarks | X7: Status | Y7: Booking Date in SAP B1 | Z7: Offer Entered in CRM | AA7: Offer Closed in CRM
A8: 1 | B8: 46023 | C8: KSB Pumps LTD | D8: Nashik | E8: Maintenance | F8: Dinkar Tarle | G8: 9960460637 | H8: dinkar.tarale@ksb.com | I8: 13004466/001 | J8: SPP | K8: Yes | L8: KXIND/W/SPP/RV25-0081 | M8: 45941 | N8: 1020260 | O8: January | P8: January | Q8: 1 | R8: 4507841035 | S8: 26/12/2025 | T8: 650474 | U8: January | V8: 0
A9: 2 | B9: 46023 | C9: ASB International | D9: Mumbai | E9: Maintenance | F9: Milind Kadam | G9: 9011049428 | H9: milind.kadam@nisseiasb.com | I9: 12005300/001 | J9: Upgradekit | K9: Yes | L9: KXIND/W/MLU/RV25-0089 | M9: 45820 | N9: 927908 | O9: January | P9: January | Q9: 1 | R9: ZPML/3610000692 | S9: 29/12/2025 | T9: 927908 | U9: January | V9: =N9-T9 -> 0
A10: 3 | B10: 46023 | C10: Mylan Laboratories LTD | D10: Aurangabad | E10: Maintenance | F10: Shahed Lathif | G10: 8888827337 | H10: shahed.lathif@viatris.com | I10: 16002947/001 | J10: SPP | K10: Yes | L10: KXIND/W/MLU/RV25-0039 | M10: 45697 | N10: 2062108 | O10: January | P10: January | Q10: 0.7 | R10: 5700206117 & 5700206651 | S10: 26/12/2025 | T10: 1838389 | U10: January | V10: 0
A11: 4 | B11: 46023 | C11: ASB International | D11: Mumbai | E11: Maintenance | F11: Milind Kadam | G11: 9011049428 | H11: milind.kadam@nisseiasb.com | I11: 12005300/001 | J11: Contract | K11: No | L11: KXIND/W/MC/RV25-088 | M11: 45820 | N11: 85700 | O11: January | P11: January | Q11: 1 | R11: ZPSC/4410000720 | S11: 19/12/2025 | T11: 82300 | U11: January | V11: 0
A12: 5 | C12: ASB International | D12: Mumbai | E12: Maintenance | F12: Milind Kadam | G12: 9011049428 | H12: milind.kadam@nisseiasb.com | I12: 12005273/001 | J12: Contract | K12: No | L12: KXIND/W/MC/RV25-088 | M12: 45820 | N12: 85700 | O12: January | P12: January | Q12: 1 | R12: ZPSC/4410000720 | S12: 19/12/2025 | T12: 82300 | U12: January | V12: 0
A13: 6 | C13: ASB International | D13: Mumbai | E13: Maintenance | F13: Milind Kadam | G13: 9011049428 | H13: milind.kadam@nisseiasb.com | I13: 12005301/001 | J13: Contract | K13: No | L13: KXIND/W/MC/RV25-088 | M13: 45820 | N13: 85700 | O13: January | P13: January | Q13: 1 | R13: ZPSC/4410000720 | S13: 19/12/2025 | T13: 82300 | U13: January | V13: 0
A14: 7 | C14: ASB International | D14: Mumbai | E14: Maintenance | F14: Milind Kadam | G14: 9011049428 | H14: milind.kadam@nisseiasb.com | I14: 14000072/001 | J14: Contract | K14: No | L14: KXIND/W/MC/RV25-088 | M14: 45820 | N14: 85700 | O14: January | P14: January | Q14: 1 | R14: ZPSC/4410000720 | S14: 19/12/2025 | T14: 82300 | U14: January | V14: 0
A15: 8 | C15: ASB International | D15: Mumbai | E15: Maintenance | F15: Milind Kadam | G15: 9011049428 | H15: milind.kadam@nisseiasb.com | I15: 14000073/001 | J15: Contract | K15: No | L15: KXIND/W/MC/RV25-088 | M15: 45820 | N15: 85700 | O15: January | P15: January | Q15: 1 | R15: ZPSC/4410000720 | S15: 19/12/2025 | T15: 82300 | U15: January | V15: 0
A16: 9 | C16: ASB International | D16: Mumbai | E16: Maintenance | F16: Milind Kadam | G16: 9011049428 | H16: milind.kadam@nisseiasb.com | I16: 15008008/001 | J16: Contract | K16: No | L16: KXIND/W/MC/RV25-088 | M16: 45820 | N16: 85700 | O16: January | P16: January | Q16: 1 | R16: ZPSC/4410000720 | S16: 19/12/2025 | T16: 82300 | U16: January | V16: 0
A17: 10 | B17: 46023 | C17: Mylan Laboratories LTD | D17: Aurangabad | E17: Engg | F17: Shahed Lathif | G17: 8888827337 | H17: shahed.lathif@viatris.com | I17: 12009614/001 | J17: Contract | K17: No | L17: KXIND/W/MC/RV25-083 | M17: 45972 | N17: 102900 | O17: January | P17: January | Q17: 1 | R17: 5700206412 | S17: 46143 | T17: 102900 | U17: January | V17: =N17-T17 -> 0
